 * Serving Flask app 'tts_server'
 * Debug mode: off
Address already in use
Port 5000 is in use by another program. Either identify and stop that program, or start the server with a different port.
register tool: search_tool
register tool: get_time_tool
register tool: calculator_tool
register tool: compare_number_tool
register tool: download_file
register tool: fix_download_file
register tool: upload_file
[91mnext_agent_tools: [StructuredTool(name='transfer_to_search_agent', description='将用户的问题转移到处理 search_agent 问题的 agent,该 agent 的能力是：你是搜索引擎的专家，能处理搜索引擎相关的问题，例如：如何搜索，如何查询，如何删除，如何添加', args_schema=<class 'langchain_core.utils.pydantic.transfer_to_search_agent'>, func=<function Agent._get_next_agent_tools.<locals>.create_transfer_func.<locals>.transfer_func at 0x7f5bc164b310>), StructuredTool(name='transfer_to_kodo_agent', description='将用户的问题转移到处理 kodo_agent 问题的 agent,该 agent 的能力是：你是kodo的专家，能处理kodo相关的问题，例如：如何上传文件到kodo，如何下载文件到kodo，如何删除文件到kodo，如何查询文件到kodo，如何添加文件到kodo', args_schema=<class 'langchain_core.utils.pydantic.transfer_to_kodo_agent'>, func=<function Agent._get_next_agent_tools.<locals>.create_transfer_func.<locals>.transfer_func at 0x7f5bc1637670>)][0m
[91mnext_agent_tools: [][0m
[91mnext_agent_tools: [][0m
[90madd agent node: router_agent[0m
[90madd agent node: kodo_agent[0m
[90madd agent node: search_agent[0m
图片已保存为 graph.png
 * Serving Flask app 'app'
 * Debug mode: off
Address already in use
Port 5001 is in use by another program. Either identify and stop that program, or start the server with a different port.
register tool: search_tool
register tool: get_time_tool
register tool: calculator_tool
register tool: compare_number_tool
register tool: download_file
register tool: fix_download_file
register tool: upload_file
[91mnext_agent_tools: [StructuredTool(name='transfer_to_search_agent', description='将用户的问题转移到处理 search_agent 问题的 agent,该 agent 的能力是：你是搜索引擎的专家，能处理搜索引擎相关的问题，例如：如何搜索，如何查询，如何删除，如何添加', args_schema=<class 'langchain_core.utils.pydantic.transfer_to_search_agent'>, func=<function Agent._get_next_agent_tools.<locals>.create_transfer_func.<locals>.transfer_func at 0x7f80ec685310>), StructuredTool(name='transfer_to_kodo_agent', description='将用户的问题转移到处理 kodo_agent 问题的 agent,该 agent 的能力是：你是kodo的专家，能处理kodo相关的问题，例如：如何上传文件到kodo，如何下载文件到kodo，如何删除文件到kodo，如何查询文件到kodo，如何添加文件到kodo', args_schema=<class 'langchain_core.utils.pydantic.transfer_to_kodo_agent'>, func=<function Agent._get_next_agent_tools.<locals>.create_transfer_func.<locals>.transfer_func at 0x7f80ec672670>)][0m
[91mnext_agent_tools: [][0m
[91mnext_agent_tools: [][0m
[90madd agent node: router_agent[0m
[90madd agent node: kodo_agent[0m
[90madd agent node: search_agent[0m
图片已保存为 graph.png
 * Serving Flask app 'app'
 * Debug mode: off
Address already in use
Port 5001 is in use by another program. Either identify and stop that program, or start the server with a different port.
预热所有进程...
所有 4 个进程已完成初始化
 * Serving Flask app 'tts_multiprocess_server'
 * Debug mode: off
[31m[1mWARNING: This is a development server. Do not use it in a production deployment. Use a production WSGI server instead.[0m
 * Running on http://127.0.0.1:5002
[33mPress CTRL+C to quit[0m
Exception in initializer:
Traceback (most recent call last):
  File "/disk1/anaconda3/envs/GPTSoVits/lib/python3.9/concurrent/futures/process.py", line 233, in _process_worker
    initializer(*initargs)
  File "/disk6/zyx/GPT-SoVITS/tts/tts_multiprocess_server.py", line 38, in init_worker
    worker_tts = TTS(config)
  File "/disk6/zyx/GPT-SoVITS/GPT_SoVITS/TTS_infer_pack/TTS.py", line 252, in __init__
    self._init_models()
  File "/disk6/zyx/GPT-SoVITS/GPT_SoVITS/TTS_infer_pack/TTS.py", line 279, in _init_models
    self.init_bert_weights(self.configs.bert_base_path)
  File "/disk6/zyx/GPT-SoVITS/GPT_SoVITS/TTS_infer_pack/TTS.py", line 300, in init_bert_weights
    self.bert_model = self.bert_model.to(self.configs.device)
  File "/disk1/anaconda3/envs/GPTSoVits/lib/python3.9/site-packages/transformers/modeling_utils.py", line 3156, in to
    return super().to(*args, **kwargs)
  File "/disk1/anaconda3/envs/GPTSoVits/lib/python3.9/site-packages/torch/nn/modules/module.py", line 1340, in to
    return self._apply(convert)
  File "/disk1/anaconda3/envs/GPTSoVits/lib/python3.9/site-packages/torch/nn/modules/module.py", line 900, in _apply
    module._apply(fn)
  File "/disk1/anaconda3/envs/GPTSoVits/lib/python3.9/site-packages/torch/nn/modules/module.py", line 900, in _apply
    module._apply(fn)
  File "/disk1/anaconda3/envs/GPTSoVits/lib/python3.9/site-packages/torch/nn/modules/module.py", line 900, in _apply
    module._apply(fn)
  [Previous line repeated 3 more times]
  File "/disk1/anaconda3/envs/GPTSoVits/lib/python3.9/site-packages/torch/nn/modules/module.py", line 927, in _apply
    param_applied = fn(param)
  File "/disk1/anaconda3/envs/GPTSoVits/lib/python3.9/site-packages/torch/nn/modules/module.py", line 1326, in convert
    return t.to(
torch.OutOfMemoryError: CUDA out of memory. Tried to allocate 16.00 MiB. GPU 0 has a total capacity of 15.77 GiB of which 4.19 MiB is free. Process 13179 has 1.60 GiB memory in use. Process 13182 has 1.55 GiB memory in use. Process 41036 has 1.59 GiB memory in use. Process 41037 has 1.58 GiB memory in use. Process 5878 has 1.55 GiB memory in use. Process 5880 has 1.61 GiB memory in use. Process 15492 has 1.93 GiB memory in use. Process 15498 has 1.88 GiB memory in use. Including non-PyTorch memory, this process has 1.54 GiB memory in use. Process 15500 has 950.00 MiB memory in use. Of the allocated memory 1.15 GiB is allocated by PyTorch, and 37.57 MiB is reserved by PyTorch but unallocated. If reserved but unallocated memory is large try setting PYTORCH_CUDA_ALLOC_CONF=expandable_segments:True to avoid fragmentation.  See documentation for Memory Management  (https://pytorch.org/docs/stable/notes/cuda.html#environment-variables)
初始化worker进程的TTS模型...
Loading Text2Semantic weights from GPT_SoVITS/pretrained_models/gsv-v2final-pretrained/s1bert25hz-5kh-longer-epoch=12-step=369668.ckpt
Loading VITS weights from GPT_SoVITS/pretrained_models/gsv-v2final-pretrained/s2G2333k.pth
Loading BERT weights from GPT_SoVITS/pretrained_models/chinese-roberta-wwm-ext-large
[2024-11-06 18:10:58,352] ERROR in app: Exception on /tts [POST]
Traceback (most recent call last):
  File "/disk1/anaconda3/envs/GPTSoVits/lib/python3.9/site-packages/flask/app.py", line 1473, in wsgi_app
    response = self.full_dispatch_request()
  File "/disk1/anaconda3/envs/GPTSoVits/lib/python3.9/site-packages/flask/app.py", line 882, in full_dispatch_request
    rv = self.handle_user_exception(e)
  File "/disk1/anaconda3/envs/GPTSoVits/lib/python3.9/site-packages/flask/app.py", line 880, in full_dispatch_request
    rv = self.dispatch_request()
  File "/disk1/anaconda3/envs/GPTSoVits/lib/python3.9/site-packages/flask/app.py", line 865, in dispatch_request
    return self.ensure_sync(self.view_functions[rule.endpoint])(**view_args)  # type: ignore[no-any-return]
  File "/disk1/anaconda3/envs/GPTSoVits/lib/python3.9/site-packages/asgiref/sync.py", line 254, in __call__
    return call_result.result()
  File "/disk1/anaconda3/envs/GPTSoVits/lib/python3.9/concurrent/futures/_base.py", line 439, in result
    return self.__get_result()
  File "/disk1/anaconda3/envs/GPTSoVits/lib/python3.9/concurrent/futures/_base.py", line 391, in __get_result
    raise self._exception
  File "/disk1/anaconda3/envs/GPTSoVits/lib/python3.9/site-packages/asgiref/sync.py", line 331, in main_wrap
    result = await self.awaitable(*args, **kwargs)
  File "/disk6/zyx/GPT-SoVITS/tts/tts_multiprocess_server.py", line 121, in tts_process
    future, req_index = worker_manager.process_request(inputs)
  File "/disk6/zyx/GPT-SoVITS/tts/tts_multiprocess_server.py", line 50, in process_request
    future = self.executor.submit(tts_worker,**data)
  File "/disk1/anaconda3/envs/GPTSoVits/lib/python3.9/concurrent/futures/process.py", line 707, in submit
    raise BrokenProcessPool(self._broken)
concurrent.futures.process.BrokenProcessPool: A child process terminated abruptly, the process pool is not usable anymore
127.0.0.1 - - [06/Nov/2024 18:10:58] "[35m[1mPOST /tts HTTP/1.1[0m" 500 -
[2024-11-06 18:10:58,559] ERROR in app: Exception on /tts [POST]
Traceback (most recent call last):
  File "/disk1/anaconda3/envs/GPTSoVits/lib/python3.9/site-packages/flask/app.py", line 1473, in wsgi_app
    response = self.full_dispatch_request()
  File "/disk1/anaconda3/envs/GPTSoVits/lib/python3.9/site-packages/flask/app.py", line 882, in full_dispatch_request
    rv = self.handle_user_exception(e)
  File "/disk1/anaconda3/envs/GPTSoVits/lib/python3.9/site-packages/flask/app.py", line 880, in full_dispatch_request
    rv = self.dispatch_request()
  File "/disk1/anaconda3/envs/GPTSoVits/lib/python3.9/site-packages/flask/app.py", line 865, in dispatch_request
    return self.ensure_sync(self.view_functions[rule.endpoint])(**view_args)  # type: ignore[no-any-return]
  File "/disk1/anaconda3/envs/GPTSoVits/lib/python3.9/site-packages/asgiref/sync.py", line 254, in __call__
    return call_result.result()
  File "/disk1/anaconda3/envs/GPTSoVits/lib/python3.9/concurrent/futures/_base.py", line 439, in result
    return self.__get_result()
  File "/disk1/anaconda3/envs/GPTSoVits/lib/python3.9/concurrent/futures/_base.py", line 391, in __get_result
    raise self._exception
  File "/disk1/anaconda3/envs/GPTSoVits/lib/python3.9/site-packages/asgiref/sync.py", line 331, in main_wrap
    result = await self.awaitable(*args, **kwargs)
  File "/disk6/zyx/GPT-SoVITS/tts/tts_multiprocess_server.py", line 121, in tts_process
    future, req_index = worker_manager.process_request(inputs)
  File "/disk6/zyx/GPT-SoVITS/tts/tts_multiprocess_server.py", line 50, in process_request
    future = self.executor.submit(tts_worker,**data)
  File "/disk1/anaconda3/envs/GPTSoVits/lib/python3.9/concurrent/futures/process.py", line 707, in submit
    raise BrokenProcessPool(self._broken)
concurrent.futures.process.BrokenProcessPool: A child process terminated abruptly, the process pool is not usable anymore
127.0.0.1 - - [06/Nov/2024 18:10:58] "[35m[1mPOST /tts HTTP/1.1[0m" 500 -
